Workbook

Sheet Cover & Guide
A1: CRM GROUP ASSIGNMENT | MOMO HUT CUSTOMER RETENTION ANALYSIS
A3: Learning Team | B3: 1
A4: Business | B4: Momo Hut
A5: Location | B5: Basant Gaon, New Delhi
A6: Business Type | B6: Quick-service Chinese restaurant / momo outlet
A7: Data Status | B7: Academic simulation — hypothetical field data
A8: Analysis Date | B8: 46265
A10: How to use this workbook
A11: 1. Customer Response Tracker: 80 anonymized simulated customer records.
A12: 2. RFM Analysis: Recency, Frequency and Monetary calculations are formula-driven.
A13: 3. Customer Segmentation: mutually exclusive RFM segments.
A14: 4. At-Risk Analysis: strict three-condition behavioural rule.
A15: 5. At-Risk Insights: reason, satisfaction and preferred-offer analysis.
A16: 6. Retention Playbook: 3 proposed measures tied to findings.
A17: 7. Implementation & Impact: timeline, KPIs, assumptions and projected impact.
A18: 8. Field Visit Log: two simulated visit records and staff/customer observation notes.
A19: Tap any calculated cell in Excel to view the formula in the formula bar.

Sheet Customer Response Tracker
A1: Momo Hut — Customer Response Tracker (80 simulated responses)
A4: Customer ID | B4: Interview Date | C4: Time Visiting Outlet | D4: Current Visits/Month | E4: Earlier Visits/Month | F4: Most Recent Visit | G4: Usual Product | H4: Average Spend (INR) | I4: Satisfaction (1-5) | J4: Visiting Less Frequently? | K4: Reason for Reduced Visits | L4: Loyalty Interest | M4: Preferred Offer | N4: Additional Feedback
A5: M001 | B5: 46258 | C5: 3 years | D5: 5 | E5: 8 | F5: 46263 | G5: Spring Rolls | H5: 369 | I5: 3 | J5: Yes | K5: Not interested in promotions | L5: Yes | M5: 10% weekday discount | N5: Would like faster service during rush hours.
A6: M002 | B6: 46263 | C6: 6 months | D6: 1 | E6: 2 | F6: 46261 | G6: Manchurian | H6: 235 | I6: 3 | J6: Yes | K6: Another food outlet opened closer | L6: No | M6: Loyalty stamp card | N6: Online ordering could be easier.
A7: M003 | B7: 46262 | C7: 1 year | D7: 1 | E7: 6 | F7: 46233 | G7: Kurkure Momos | H7: 402 | I7: 2 | J7: Yes | K7: Food taste has become inconsistent on recent visits | L7: Maybe | M7: Combo meal deal | N7: Packaging for takeaway could improve.
A8: M004 | B8: 46262 | C8: 2 months | D8: 6 | E8: 4 | F8: 46253 | G8: Manchurian | H8: 206 | I8: 2 | J8: No | L8: Yes | M8: Combo meal deal | N8: Good value for money.
A9: M005 | B9: 46259 | C9: 4 years | D9: 2 | E9: 3 | F9: 46221 | G9: Fried Momos | H9: 430 | I9: 3 | J9: Yes | K9: Busy schedule has reduced my visits | L9: No | M9: Combo meal deal | N9: Good value for money.
A10: M006 | B10: 46258 | C10: 2 years | D10: 3 | E10: 2 | F10: 46256 | G10: Fried Rice | H10: 377 | I10: 3 | J10: No | L10: Yes | M10: Not interested | N10: Online ordering could be easier.
A11: M007 | B11: 46258 | C11: 3 years | D11: 7 | E11: 6 | F11: 46237 | G11: Kurkure Momos | H11: 273 | I11: 2 | J11: No | L11: Maybe | M11: 10% weekday discount | N11: Would like more variety in sauces and dips.
A12: M008 | B12: 46262 | C12: 2 months | D12: 1 | E12: 7 | F12: 46232 | G12: Hakka Noodles | H12: 221 | I12: 3 | J12: Yes | K12: Service is slow during the evening rush | L12: Yes | M12: 10% weekday discount | N12: Online ordering could be easier.
A13: M009 | B13: 46259 | C13: 4 years | D13: 4 | E13: 2 | F13: 46253 | G13: Manchurian | H13: 282 | I13: 3 | J13: No | L13: Yes | M13: Referral reward | N13: Good value for money.
A14: M010 | B14: 46263 | C14: 3 years | D14: 6 | E14: 5 | F14: 46249 | G14: Spring Rolls | H14: 216 | I14: 3 | J14: No | L14: Yes | M14: Birthday offer | N14: Would like more variety in sauces and dips.
A15: M011 | B15: 46259 | C15: 4 years | D15: 3 | E15: 5 | F15: 46259 | G15: Kurkure Momos | H15: 310 | I15: 4 | J15: Yes | K15: Work schedule has changed | L15: Yes | M15: Not interested | N15: Would like faster service during rush hours.
A16: M012 | B16: 46258 | C16: 4 years | D16: 1 | E16: 8 | F16: 46230 | G16: Fried Momos | H16: 196 | I16: 2 | J16: Yes | K16: Portion size feels smaller than before | L16: Maybe | M16: Free beverage add-on | N16: Would like more variety in sauces and dips.
A17: M013 | B17: 46263 | C17: 6 months | D17: 8 | E17: 8 | F17: 46239 | G17: Manchurian | H17: 248 | I17: 4 | J17: No | L17: Maybe | M17: Loyalty stamp card | N17: Would like more variety in sauces and dips.
A18: M014 | B18: 46262 | C18: 4 years | D18: 3 | E18: 2 | F18: 46240 | G18: Hot & Sour Soup | H18: 247 | I18: 5 | J18: No | L18: Yes | M18: Referral reward | N18: Would like faster service during rush hours.
A19: M015 | B19: 46262 | C19: 2 years | D19: 5 | E19: 7 | F19: 46259 | G19: Steamed Momos | H19: 275 | I19: 4 | J19: Yes | K19: Need more vegetarian choices | L19: No | M19: Not interested | N19: Taste is consistent and portions are good.
A20: M016 | B20: 46258 | C20: 4 years | D20: 1 | E20: 6 | F20: 46227 | G20: Manchurian | H20: 386 | I20: 1 | J20: Yes | K20: Started working from home, so the outlet is less convenient | L20: Yes | M20: Loyalty stamp card | N20: Would like faster service during rush hours.
A21: M017 | B21: 46262 | C21: 3 years | D21: 5 | E21: 3 | F21: 46246 | G21: Combo Meal | H21: 376 | I21: 2 | J21: No | L21: No | M21: Free beverage add-on | N21: More seating would be useful.
A22: M018 | B22: 46263 | C22: 4 years | D22: 3 | E22: 5 | F22: 46246 | G22: Chilli Paneer | H22: 373 | I22: 4 | J22: Yes | K22: Another food outlet opened closer | L22: Yes | M22: Birthday offer | N22: Would like more variety in sauces and dips.
A23: M019 | B23: 46259 | C23: 3 years | D23: 6 | E23: 6 | F23: 46249 | G23: Hakka Noodles | H23: 210 | I23: 3 | J23: No | L23: Yes | M23: Combo meal deal | N23: Taste is consistent and portions are good.
A24: M020 | B24: 46258 | C24: 3 years | D24: 2 | E24: 8 | F24: 46215 | G24: Hakka Noodles | H24: 341 | I24: 4 | J24: Yes | K24: Too much waiting time for takeaway orders | L24: Maybe | M24: 10% weekday discount | N24: Good value for money.
A25: M021 | B25: 46259 | C25: 2 years | D25: 5 | E25: 4 | F25: 46248 | G25: Spring Rolls | H25: 234 | I25: 4 | J25: No | L25: No | M25: Referral reward | N25: Would like more meal combos.
A26: M022 | B26: 46258 | C26: 4 years | D26: 1 | E26: 4 | F26: 46260 | G26: Fried Momos | H26: 348 | I26: 3 | J26: Yes | K26: Not interested in promotions | L26: Maybe | M26: Free beverage add-on | N26: Would like more meal combos.
A27: M023 | B27: 46259 | C27: 3 years | D27: 2 | E27: 2 | F27: 46240 | G27: Manchurian | H27: 266 | I27: 4 | J27: No | L27: Yes | M27: 10% weekday discount | N27: Online ordering could be easier.
A28: M024 | B28: 46258 | C28: 4 years | D28: 3 | E28: 3 | F28: 46258 | G28: Hot & Sour Soup | H28: 251 | I28: 4 | J28: No | L28: Yes | M28: Free beverage add-on | N28: Would like faster service during rush hours.
A29: M025 | B29: 46259 | C29: 2 years | D29: 3 | E29: 5 | F29: 46222 | G29: Steamed Momos | H29: 397 | I29: 3 | J29: Yes | K29: Would like more affordable combo options | L29: Maybe | M29: Combo meal deal | N29: Would like more meal combos.
A30: M026 | B30: 46263 | C30: 6 months | D30: 3 | E30: 3 | F30: 46263 | G30: Hakka Noodles | H30: 279 | I30: 3 | J30: No | L30: Maybe | M30: Combo meal deal | N30: Packaging for takeaway could improve.
A31: M027 | B31: 46258 | C31: 2 months | D31: 2 | E31: 4 | F31: 46262 | G31: Combo Meal | H31: 328 | I31: 4 | J31: Yes | K31: Another food outlet opened closer | L31: Yes | M31: Birthday offer | N31: Good value for money.
A32: M028 | B32: 46258 | C32: 3 years | D32: 6 | E32: 6 | F32: 46247 | G32: Fried Momos | H32: 220 | I32: 2 | J32: No | L32: No | M32: Loyalty stamp card | N32: More seating would be useful.
A33: M029 | B33: 46258 | C33: 2 years | D33: 10 | E33: 8 | F33: 46256 | G33: Combo Meal | H33: 283 | I33: 2 | J33: No | L33: No | M33: 10% weekday discount | N33: Taste is consistent and portions are good.
A34: M030 | B34: 46259 | C34: 1 year | D34: 7 | E34: 7 | F34: 46253 | G34: Spring Rolls | H34: 419 | I34: 3 | J34: No | L34: No | M34: Birthday offer | N34: Good value for money.
A35: M031 | B35: 46258 | C35: 2 months | D35: 3 | E35: 6 | F35: 46221 | G35: Hot & Sour Soup | H35: 256 | I35: 2 | J35: Yes | K35: Dining area feels crowded at peak hours | L35: Yes | M35: Loyalty stamp card | N35: Would like more meal combos.
A36: M032 | B36: 46262 | C36: 6 months | D36: 4 | E36: 4 | F36: 46255 | G36: Manchurian | H36: 213 | I36: 5 | J36: No | L36: Yes | M36: 10% weekday discount | N36: Good value for money.
A37: M033 | B37: 46262 | C37: 4 years | D37: 7 | E37: 6 | F37: 46254 | G37: Fried Momos | H37: 336 | I37: 5 | J37: No | L37: No | M37: Referral reward | N37: Taste is consistent and portions are good.
A38: M034 | B38: 46262 | C38: 3 years | D38: 2 | E38: 3 | F38: 46260 | G38: Hakka Noodles | H38: 407 | I38: 2 | J38: Yes | K38: Waiting time is higher on weekends | L38: No | M38: 10% weekday discount | N38: Would like more variety in sauces and dips.
A39: M035 | B39: 46262 | C39: 2 months | D39: 8 | E39: 9 | F39: 46257 | G39: Fried Momos | H39: 355 | I39: 4 | J39: Yes | K39: Another food outlet opened closer | L39: Maybe | M39: Referral reward | N39: Would like more meal combos.
A40: M036 | B40: 46262 | C40: 6 months | D40: 8 | E40: 8 | F40: 46237 | G40: Manchurian | H40: 250 | I40: 1 | J40: No | L40: Maybe | M40: Not interested | N40: More seating would be useful.
A41: M037 | B41: 46258 | C41: 1 year | D41: 3 | E41: 8 | F41: 46233 | G41: Combo Meal | H41: 323 | I41: 4 | J41: Yes | K41: Menu has not changed much in recent months | L41: Maybe | M41: Free beverage add-on | N41: More seating would be useful.
A42: M038 | B42: 46262 | C42: 6 months | D42: 4 | E42: 6 | F42: 46250 | G42: Hakka Noodles | H42: 212 | I42: 1 | J42: Yes | K42: Work schedule has changed | L42: Maybe | M42: Not interested | N42: Taste is consistent and portions are good.
...

Sheet RFM Analysis
A1: Momo Hut — RFM Analysis
A2: Fixed analysis date | B2: 46265 | D2: RFM Score = R + F + M
A4: Customer ID | B4: Most Recent Visit | C4: Recency Days | D4: R Score | E4: Current Visits/Month | F4: F Score | G4: Average Spend/Visit | H4: M Score | I4: RFM Score | J4: F Rank | K4: M Rank | L4: Segment Link
A5: ='Customer Response Tracker'!A5 -> M001 | B5: ='Customer Response Tracker'!F5 -> 46263 | C5: =$B$2-B5 -> 2 | D5: =IF(C5<=7,5,IF(C5<=15,4,IF(C5<=30,3,IF(C5<=45,2,1)))) -> 5 | E5: ='Customer Response Tracker'!D5 -> 5 | F5: =5-INT((RANK(E5,$E$5:$E$84,0)-1)/16) -> 4 | G5: ='Customer Response Tracker'!H5 -> 369 | H5: =5-INT((RANK(G5,$G$5:$G$84,0)-1)/16) -> 4 | I5: =D5+F5+H5 -> 13 | J5: =RANK(E5,$E$5:$E$84,0) -> 27 | K5: =RANK(G5,$G$5:$G$84,0) -> 19 | L5: ='Customer Segmentation'!F5 -> Champions / Highly Loyal
A6: ='Customer Response Tracker'!A6 -> M002 | B6: ='Customer Response Tracker'!F6 -> 46261 | C6: =$B$2-B6 -> 4 | D6: =IF(C6<=7,5,IF(C6<=15,4,IF(C6<=30,3,IF(C6<=45,2,1)))) -> 5 | E6: ='Customer Response Tracker'!D6 -> 1 | F6: =5-INT((RANK(E6,$E$5:$E$84,0)-1)/16) -> 1 | G6: ='Customer Response Tracker'!H6 -> 235 | H6: =5-INT((RANK(G6,$G$5:$G$84,0)-1)/16) -> 1 | I6: =D6+F6+H6 -> 7 | J6: =RANK(E6,$E$5:$E$84,0) -> 70 | K6: =RANK(G6,$G$5:$G$84,0) -> 67 | L6: ='Customer Segmentation'!F6 -> Potential Loyalists
A7: ='Customer Response Tracker'!A7 -> M003 | B7: ='Customer Response Tracker'!F7 -> 46233 | C7: =$B$2-B7 -> 32 | D7: =IF(C7<=7,5,IF(C7<=15,4,IF(C7<=30,3,IF(C7<=45,2,1)))) -> 2 | E7: ='Customer Response Tracker'!D7 -> 1 | F7: =5-INT((RANK(E7,$E$5:$E$84,0)-1)/16) -> 1 | G7: ='Customer Response Tracker'!H7 -> 402 | H7: =5-INT((RANK(G7,$G$5:$G$84,0)-1)/16) -> 5 | I7: =D7+F7+H7 -> 8 | J7: =RANK(E7,$E$5:$E$84,0) -> 70 | K7: =RANK(G7,$G$5:$G$84,0) -> 5 | L7: ='Customer Segmentation'!F7 -> At-Risk Customers
A8: ='Customer Response Tracker'!A8 -> M004 | B8: ='Customer Response Tracker'!F8 -> 46253 | C8: =$B$2-B8 -> 12 | D8: =IF(C8<=7,5,IF(C8<=15,4,IF(C8<=30,3,IF(C8<=45,2,1)))) -> 4 | E8: ='Customer Response Tracker'!D8 -> 6 | F8: =5-INT((RANK(E8,$E$5:$E$84,0)-1)/16) -> 4 | G8: ='Customer Response Tracker'!H8 -> 206 | H8: =5-INT((RANK(G8,$G$5:$G$84,0)-1)/16) -> 1 | I8: =D8+F8+H8 -> 9 | J8: =RANK(E8,$E$5:$E$84,0) -> 18 | K8: =RANK(G8,$G$5:$G$84,0) -> 79 | L8: ='Customer Segmentation'!F8 -> Potential Loyalists
A9: ='Customer Response Tracker'!A9 -> M005 | B9: ='Customer Response Tracker'!F9 -> 46221 | C9: =$B$2-B9 -> 44 | D9: =IF(C9<=7,5,IF(C9<=15,4,IF(C9<=30,3,IF(C9<=45,2,1)))) -> 2 | E9: ='Customer Response Tracker'!D9 -> 2 | F9: =5-INT((RANK(E9,$E$5:$E$84,0)-1)/16) -> 2 | G9: ='Customer Response Tracker'!H9 -> 430 | H9: =5-INT((RANK(G9,$G$5:$G$84,0)-1)/16) -> 5 | I9: =D9+F9+H9 -> 9 | J9: =RANK(E9,$E$5:$E$84,0) -> 57 | K9: =RANK(G9,$G$5:$G$84,0) -> 1 | L9: ='Customer Segmentation'!F9 -> At-Risk Customers
A10: ='Customer Response Tracker'!A10 -> M006 | B10: ='Customer Response Tracker'!F10 -> 46256 | C10: =$B$2-B10 -> 9 | D10: =IF(C10<=7,5,IF(C10<=15,4,IF(C10<=30,3,IF(C10<=45,2,1)))) -> 4 | E10: ='Customer Response Tracker'!D10 -> 3 | F10: =5-INT((RANK(E10,$E$5:$E$84,0)-1)/16) -> 3 | G10: ='Customer Response Tracker'!H10 -> 377 | H10: =5-INT((RANK(G10,$G$5:$G$84,0)-1)/16) -> 5 | I10: =D10+F10+H10 -> 12 | J10: =RANK(E10,$E$5:$E$84,0) -> 46 | K10: =RANK(G10,$G$5:$G$84,0) -> 13 | L10: ='Customer Segmentation'!F10 -> Loyal Customers
A11: ='Customer Response Tracker'!A11 -> M007 | B11: ='Customer Response Tracker'!F11 -> 46237 | C11: =$B$2-B11 -> 28 | D11: =IF(C11<=7,5,IF(C11<=15,4,IF(C11<=30,3,IF(C11<=45,2,1)))) -> 3 | E11: ='Customer Response Tracker'!D11 -> 7 | F11: =5-INT((RANK(E11,$E$5:$E$84,0)-1)/16) -> 5 | G11: ='Customer Response Tracker'!H11 -> 273 | H11: =5-INT((RANK(G11,$G$5:$G$84,0)-1)/16) -> 2 | I11: =D11+F11+H11 -> 10 | J11: =RANK(E11,$E$5:$E$84,0) -> 11 | K11: =RANK(G11,$G$5:$G$84,0) -> 51 | L11: ='Customer Segmentation'!F11 -> Inactive / Low Engagement
A12: ='Customer Response Tracker'!A12 -> M008 | B12: ='Customer Response Tracker'!F12 -> 46232 | C12: =$B$2-B12 -> 33 | D12: =IF(C12<=7,5,IF(C12<=15,4,IF(C12<=30,3,IF(C12<=45,2,1)))) -> 2 | E12: ='Customer Response Tracker'!D12 -> 1 | F12: =5-INT((RANK(E12,$E$5:$E$84,0)-1)/16) -> 1 | G12: ='Customer Response Tracker'!H12 -> 221 | H12: =5-INT((RANK(G12,$G$5:$G$84,0)-1)/16) -> 1 | I12: =D12+F12+H12 -> 4 | J12: =RANK(E12,$E$5:$E$84,0) -> 70 | K12: =RANK(G12,$G$5:$G$84,0) -> 71 | L12: ='Customer Segmentation'!F12 -> At-Risk Customers
A13: ='Customer Response Tracker'!A13 -> M009 | B13: ='Customer Response Tracker'!F13 -> 46253 | C13: =$B$2-B13 -> 12 | D13: =IF(C13<=7,5,IF(C13<=15,4,IF(C13<=30,3,IF(C13<=45,2,1)))) -> 4 | E13: ='Customer Response Tracker'!D13 -> 4 | F13: =5-INT((RANK(E13,$E$5:$E$84,0)-1)/16) -> 3 | G13: ='Customer Response Tracker'!H13 -> 282 | H13: =5-INT((RANK(G13,$G$5:$G$84,0)-1)/16) -> 3 | I13: =D13+F13+H13 -> 10 | J13: =RANK(E13,$E$5:$E$84,0) -> 39 | K13: =RANK(G13,$G$5:$G$84,0) -> 45 | L13: ='Customer Segmentation'!F13 -> Loyal Customers
A14: ='Customer Response Tracker'!A14 -> M010 | B14: ='Customer Response Tracker'!F14 -> 46249 | C14: =$B$2-B14 -> 16 | D14: =IF(C14<=7,5,IF(C14<=15,4,IF(C14<=30,3,IF(C14<=45,2,1)))) -> 3 | E14: ='Customer Response Tracker'!D14 -> 6 | F14: =5-INT((RANK(E14,$E$5:$E$84,0)-1)/16) -> 4 | G14: ='Customer Response Tracker'!H14 -> 216 | H14: =5-INT((RANK(G14,$G$5:$G$84,0)-1)/16) -> 1 | I14: =D14+F14+H14 -> 8 | J14: =RANK(E14,$E$5:$E$84,0) -> 18 | K14: =RANK(G14,$G$5:$G$84,0) -> 73 | L14: ='Customer Segmentation'!F14 -> Inactive / Low Engagement
A15: ='Customer Response Tracker'!A15 -> M011 | B15: ='Customer Response Tracker'!F15 -> 46259 | C15: =$B$2-B15 -> 6 | D15: =IF(C15<=7,5,IF(C15<=15,4,IF(C15<=30,3,IF(C15<=45,2,1)))) -> 5 | E15: ='Customer Response Tracker'!D15 -> 3 | F15: =5-INT((RANK(E15,$E$5:$E$84,0)-1)/16) -> 3 | G15: ='Customer Response Tracker'!H15 -> 310 | H15: =5-INT((RANK(G15,$G$5:$G$84,0)-1)/16) -> 3 | I15: =D15+F15+H15 -> 11 | J15: =RANK(E15,$E$5:$E$84,0) -> 46 | K15: =RANK(G15,$G$5:$G$84,0) -> 37 | L15: ='Customer Segmentation'!F15 -> Loyal Customers
A16: ='Customer Response Tracker'!A16 -> M012 | B16: ='Customer Response Tracker'!F16 -> 46230 | C16: =$B$2-B16 -> 35 | D16: =IF(C16<=7,5,IF(C16<=15,4,IF(C16<=30,3,IF(C16<=45,2,1)))) -> 2 | E16: ='Customer Response Tracker'!D16 -> 1 | F16: =5-INT((RANK(E16,$E$5:$E$84,0)-1)/16) -> 1 | G16: ='Customer Response Tracker'!H16 -> 196 | H16: =5-INT((RANK(G16,$G$5:$G$84,0)-1)/16) -> 1 | I16: =D16+F16+H16 -> 4 | J16: =RANK(E16,$E$5:$E$84,0) -> 70 | K16: =RANK(G16,$G$5:$G$84,0) -> 80 | L16: ='Customer Segmentation'!F16 -> At-Risk Customers
... A84: ='Customer Response Tracker'!A84 -> M080 | B84: ='Customer Response Tracker'!F84 -> 46239 | C84: =$B$2-B84 -> 26 | D84: =IF(C84<=7,5,IF(C84<=15,4,IF(C84<=30,3,IF(C84<=45,2,1)))) -> 3 | E84: ='Customer Response Tracker'!D84 -> 10 | F84: =5-INT((RANK(E84,$E$5:$E$84,0)-1)/16) -> 5 | G84: ='Customer Response Tracker'!H84 -> 305 | H84: =5-INT((RANK(G84,$G$5:$G$84,0)-1)/16) -> 3 | I84: =D84+F84+H84 -> 11 | J84: =RANK(E84,$E$5:$E$84,0) -> 1 | K84: =RANK(G84,$G$5:$G$84,0) -> 40 | L84: ='Customer Segmentation'!F84 -> Loyal Customers
A87: RFM scoring rules
A88: R: 0–7 days=5; 8–15=4; 16–30=3; 31–45=2; >45=1
A89: F & M: rank customers high-to-low and assign quintile scores 5 to 1 using 16-customer blocks.
A90: Lower Recency Days = better; higher Frequency and Monetary = better.

Sheet Customer Segmentation
A1: Momo Hut — Customer Segmentation
A2: Segments are mutually exclusive and assigned in priority order.
A4: Customer ID | B4: RFM Score | C4: R Score | D4: F Score | E4: M Score | F4: Segment | G4: Segment Logic | H4: Recommended CRM Focus
A5: ='RFM Analysis'!A5 -> M001 | B5: ='RFM Analysis'!I5 -> 13 | C5: ='RFM Analysis'!D5 -> 5 | D5: ='RFM Analysis'!F5 -> 4 | E5: ='RFM Analysis'!H5 -> 4 | F5: =IF(AND(C5>=4,D5>=4,E5>=4),"Champions / Highly Loyal",IF(AND(C5>=3,D5>=3,E5>=3),"Loyal Customers",IF(AND(C5<=2,OR(D5>=3,E5>=3,'Customer Response Tracker'!J5="Yes")),"At-Risk Customers",IF(C5>=4,"Potential Loyalists","Inactive / Low Engagement")))) -> Champions / Highly Loyal | G5: =IF(F5="Champions / Highly Loyal","R, F and M all ≥4",IF(F5="Loyal Customers","R, F and M all ≥3, but not Champion",IF(F5="At-Risk Customers","R≤2 and F≥3 or M≥3 or self-reported decline","Remaining customer group"))) -> R, F and M all ≥4 | H5: =IF(F5="Champions / Highly Loyal","Advocacy, recognition and premium loyalty",IF(F5="Loyal Customers","Cross-sell, bundles and loyalty",IF(F5="Potential Loyalists","Build frequency and basket size",IF(F5="At-Risk Customers","Personalized win-back and service recovery","Low-cost reactivation / selective offers")))) -> Advocacy, recognition and premium loyalty
A6: ='RFM Analysis'!A6 -> M002 | B6: ='RFM Analysis'!I6 -> 7 | C6: ='RFM Analysis'!D6 -> 5 | D6: ='RFM Analysis'!F6 -> 1 | E6: ='RFM Analysis'!H6 -> 1 | F6: =IF(AND(C6>=4,D6>=4,E6>=4),"Champions / Highly Loyal",IF(AND(C6>=3,D6>=3,E6>=3),"Loyal Customers",IF(AND(C6<=2,OR(D6>=3,E6>=3,'Customer Response Tracker'!J6="Yes")),"At-Risk Customers",IF(C6>=4,"Potential Loyalists","Inactive / Low Engagement")))) -> Potential Loyalists | G6: =IF(F6="Champions / Highly Loyal","R, F and M all ≥4",IF(F6="Loyal Customers","R, F and M all ≥3, but not Champion",IF(F6="At-Risk Customers","R≤2 and F≥3 or M≥3 or self-reported decline","Remaining customer group"))) -> Remaining customer group | H6: =IF(F6="Champions / Highly Loyal","Advocacy, recognition and premium loyalty",IF(F6="Loyal Customers","Cross-sell, bundles and loyalty",IF(F6="Potential Loyalists","Build frequency and basket size",IF(F6="At-Risk Customers","Personalized win-back and service recovery","Low-cost reactivation / selective offers")))) -> Build frequency and basket size
A7: ='RFM Analysis'!A7 -> M003 | B7: ='RFM Analysis'!I7 -> 8 | C7: ='RFM Analysis'!D7 -> 2 | D7: ='RFM Analysis'!F7 -> 1 | E7: ='RFM Analysis'!H7 -> 5 | F7: =IF(AND(C7>=4,D7>=4,E7>=4),"Champions / Highly Loyal",IF(AND(C7>=3,D7>=3,E7>=3),"Loyal Customers",IF(AND(C7<=2,OR(D7>=3,E7>=3,'Customer Response Tracker'!J7="Yes")),"At-Risk Customers",IF(C7>=4,"Potential Loyalists","Inactive / Low Engagement")))) -> At-Risk Customers | G7: =IF(F7="Champions / Highly Loyal","R, F and M all ≥4",IF(F7="Loyal Customers","R, F and M all ≥3, but not Champion",IF(F7="At-Risk Customers","R≤2 and F≥3 or M≥3 or self-reported decline","Remaining customer group"))) -> R≤2 and F≥3 or M≥3 or self-reported decline | H7: =IF(F7="Champions / Highly Loyal","Advocacy, recognition and premium loyalty",IF(F7="Loyal Customers","Cross-sell, bundles and loyalty",IF(F7="Potential Loyalists","Build frequency and basket size",IF(F7="At-Risk Customers","Personalized win-back and service recovery","Low-cost reactivation / selective offers")))) -> Personalized win-back and service recovery
A8: ='RFM Analysis'!A8 -> M004 | B8: ='RFM Analysis'!I8 -> 9 | C8: ='RFM Analysis'!D8 -> 4 | D8: ='RFM Analysis'!F8 -> 4 | E8: ='RFM Analysis'!H8 -> 1 | F8: =IF(AND(C8>=4,D8>=4,E8>=4),"Champions / Highly Loyal",IF(AND(C8>=3,D8>=3,E8>=3),"Loyal Customers",IF(AND(C8<=2,OR(D8>=3,E8>=3,'Customer Response Tracker'!J8="Yes")),"At-Risk Customers",IF(C8>=4,"Potential Loyalists","Inactive / Low Engagement")))) -> Potential Loyalists | G8: =IF(F8="Champions / Highly Loyal","R, F and M all ≥4",IF(F8="Loyal Customers","R, F and M all ≥3, but not Champion",IF(F8="At-Risk Customers","R≤2 and F≥3 or M≥3 or self-reported decline","Remaining customer group"))) -> Remaining customer group | H8: =IF(F8="Champions / Highly Loyal","Advocacy, recognition and premium loyalty",IF(F8="Loyal Customers","Cross-sell, bundles and loyalty",IF(F8="Potential Loyalists","Build frequency and basket size",IF(F8="At-Risk Customers","Personalized win-back and service recovery","Low-cost reactivation / selective offers")))) -> Build frequency and basket size
A9: ='RFM Analysis'!A9 -> M005 | B9: ='RFM Analysis'!I9 -> 9 | C9: ='RFM Analysis'!D9 -> 2 | D9: ='RFM Analysis'!F9 -> 2 | E9: ='RFM Analysis'!H9 -> 5 | F9: =IF(AND(C9>=4,D9>=4,E9>=4),"Champions / Highly Loyal",IF(AND(C9>=3,D9>=3,E9>=3),"Loyal Customers",IF(AND(C9<=2,OR(D9>=3,E9>=3,'Customer Response Tracker'!J9="Yes")),"At-Risk Customers",IF(C9>=4,"Potential Loyalists","Inactive / Low Engagement")))) -> At-Risk Customers | G9: =IF(F9="Champions / Highly Loyal","R, F and M all ≥4",IF(F9="Loyal Customers","R, F and M all ≥3, but not Champion",IF(F9="At-Risk Customers","R≤2 and F≥3 or M≥3 or self-reported decline","Remaining customer group"))) -> R≤2 and F≥3 or M≥3 or self-reported decline | H9: =IF(F9="Champions / Highly Loyal","Advocacy, recognition and premium loyalty",IF(F9="Loyal Customers","Cross-sell, bundles and loyalty",IF(F9="Potential Loyalists","Build frequency and basket size",IF(F9="At-Risk Customers","Personalized win-back and service recovery","Low-cost reactivation / selective offers")))) -> Personalized win-back and service recovery
A10: ='RFM Analysis'!A10 -> M006 | B10: ='RFM Analysis'!I10 -> 12 | C10: ='RFM Analysis'!D10 -> 4 | D10: ='RFM Analysis'!F10 -> 3 | E10: ='RFM Analysis'!H10 -> 5 | F10: =IF(AND(C10>=4,D10>=4,E10>=4),"Champions / Highly Loyal",IF(AND(C10>=3,D10>=3,E10>=3),"Loyal Customers",IF(AND(C10<=2,OR(D10>=3,E10>=3,'Customer Response Tracker'!J10="Yes")),"At-Risk Customers",IF(C10>=4,"Potential Loyalists","Inactive / Low Engagement")))) -> Loyal Customers | G10: =IF(F10="Champions / Highly Loyal","R, F and M all ≥4",IF(F10="Loyal Customers","R, F and M all ≥3, but not Champion",IF(F10="At-Risk Customers","R≤2 and F≥3 or M≥3 or self-reported decline","Remaining customer group"))) -> R, F and M all ≥3, but not Champion | H10: =IF(F10="Champions / Highly Loyal","Advocacy, recognition and premium loyalty",IF(F10="Loyal Customers","Cross-sell, bundles and loyalty",IF(F10="Potential Loyalists","Build frequency and basket size",IF(F10="At-Risk Customers","Personalized win-back and service recovery","Low-cost reactivation / selective offers")))) -> Cross-sell, bundles and loyalty
A11: ='RFM Analysis'!A11 -> M007 | B11: ='RFM Analysis'!I11 -> 10 | C11: ='RFM Analysis'!D11 -> 3 | D11: ='RFM Analysis'!F11 -> 5 | E11: ='RFM Analysis'!H11 -> 2 | F11: =IF(AND(C11>=4,D11>=4,E11>=4),"Champions / Highly Loyal",IF(AND(C11>=3,D11>=3,E11>=3),"Loyal Customers",IF(AND(C11<=2,OR(D11>=3,E11>=3,'Customer Response Tracker'!J11="Yes")),"At-Risk Customers",IF(C11>=4,"Potential Loyalists","Inactive / Low Engagement")))) -> Inactive / Low Engagement | G11: =IF(F11="Champions / Highly Loyal","R, F and M all ≥4",IF(F11="Loyal Customers","R, F and M all ≥3, but not Champion",IF(F11="At-Risk Customers","R≤2 and F≥3 or M≥3 or self-reported decline","Remaining customer group"))) -> Remaining customer group | H11: =IF(F11="Champions / Highly Loyal","Advocacy, recognition and premium loyalty",IF(F11="Loyal Customers","Cross-sell, bundles and loyalty",IF(F11="Potential Loyalists","Build frequency and basket size",IF(F11="At-Risk Customers","Personalized win-back and service recovery","Low-cost reactivation / selective offers")))) -> Low-cost reactivation / selective offers
A12: ='RFM Analysis'!A12 -> M008 | B12: ='RFM Analysis'!I12 -> 4 | C12: ='RFM Analysis'!D12 -> 2 | D12: ='RFM Analysis'!F12 -> 1 | E12: ='RFM Analysis'!H12 -> 1 | F12: =IF(AND(C12>=4,D12>=4,E12>=4),"Champions / Highly Loyal",IF(AND(C12>=3,D12>=3,E12>=3),"Loyal Customers",IF(AND(C12<=2,OR(D12>=3,E12>=3,'Customer Response Tracker'!J12="Yes")),"At-Risk Customers",IF(C12>=4,"Potential Loyalists","Inactive / Low Engagement")))) -> At-Risk Customers | G12: =IF(F12="Champions / Highly Loyal","R, F and M all ≥4",IF(F12="Loyal Customers","R, F and M all ≥3, but not Champion",IF(F12="At-Risk Customers","R≤2 and F≥3 or M≥3 or self-reported decline","Remaining customer group"))) -> R≤2 and F≥3 or M≥3 or self-reported decline | H12: =IF(F12="Champions / Highly Loyal","Advocacy, recognition and premium loyalty",IF(F12="Loyal Customers","Cross-sell, bundles and loyalty",IF(F12="Potential Loyalists","Build frequency and basket size",IF(F12="At-Risk Customers","Personalized win-back and service recovery","Low-cost reactivation / selective offers")))) -> Personalized win-back and service recovery
A13: ='RFM Analysis'!A13 -> M009 | B13: ='RFM Analysis'!I13 -> 10 | C13: ='RFM Analysis'!D13 -> 4 | D13: ='RFM Analysis'!F13 -> 3 | E13: ='RFM Analysis'!H13 -> 3 | F13: =IF(AND(C13>=4,D13>=4,E13>=4),"Champions / Highly Loyal",IF(AND(C13>=3,D13>=3,E13>=3),"Loyal Customers",IF(AND(C13<=2,OR(D13>=3,E13>=3,'Customer Response Tracker'!J13="Yes")),"At-Risk Customers",IF(C13>=4,"Potential Loyalists","Inactive / Low Engagement")))) -> Loyal Customers | G13: =IF(F13="Champions / Highly Loyal","R, F and M all ≥4",IF(F13="Loyal Customers","R, F and M all ≥3, but not Champion",IF(F13="At-Risk Customers","R≤2 and F≥3 or M≥3 or self-reported decline","Remaining customer group"))) -> R, F and M all ≥3, but not Champion | H13: =IF(F13="Champions / Highly Loyal","Advocacy, recognition and premium loyalty",IF(F13="Loyal Customers","Cross-sell, bundles and loyalty",IF(F13="Potential Loyalists","Build frequency and basket size",IF(F13="At-Risk Customers","Personalized win-back and service recovery","Low-cost reactivation / selective offers")))) -> Cross-sell, bundles and loyalty
A14: ='RFM Analysis'!A14 -> M010 | B14: ='RFM Analysis'!I14 -> 8 | C14: ='RFM Analysis'!D14 -> 3 | D14: ='RFM Analysis'!F14 -> 4 | E14: ='RFM Analysis'!H14 -> 1 | F14: =IF(AND(C14>=4,D14>=4,E14>=4),"Champions / Highly Loyal",IF(AND(C14>=3,D14>=3,E14>=3),"Loyal Customers",IF(AND(C14<=2,OR(D14>=3,E14>=3,'Customer Response Tracker'!J14="Yes")),"At-Risk Customers",IF(C14>=4,"Potential Loyalists","Inactive / Low Engagement")))) -> Inactive / Low Engagement | G14: =IF(F14="Champions / Highly Loyal","R, F and M all ≥4",IF(F14="Loyal Customers","R, F and M all ≥3, but not Champion",IF(F14="At-Risk Customers","R≤2 and F≥3 or M≥3 or self-reported decline","Remaining customer group"))) -> Remaining customer group | H14: =IF(F14="Champions / Highly Loyal","Advocacy, recognition and premium loyalty",IF(F14="Loyal Customers","Cross-sell, bundles and loyalty",IF(F14="Potential Loyalists","Build frequency and basket size",IF(F14="At-Risk Customers","Personalized win-back and service recovery","Low-cost reactivation / selective offers")))) -> Low-cost reactivation / selective offers
A15: ='RFM Analysis'!A15 -> M011 | B15: ='RFM Analysis'!I15 -> 11 | C15: ='RFM Analysis'!D15 -> 5 | D15: ='RFM Analysis'!F15 -> 3 | E15: ='RFM Analysis'!H15 -> 3 | F15: =IF(AND(C15>=4,D15>=4,E15>=4),"Champions / Highly Loyal",IF(AND(C15>=3,D15>=3,E15>=3),"Loyal Customers",IF(AND(C15<=2,OR(D15>=3,E15>=3,'Customer Response Tracker'!J15="Yes")),"At-Risk Customers",IF(C15>=4,"Potential Loyalists","Inactive / Low Engagement")))) -> Loyal Customers | G15: =IF(F15="Champions / Highly Loyal","R, F and M all ≥4",IF(F15="Loyal Customers","R, F and M all ≥3, but not Champion",IF(F15="At-Risk Customers","R≤2 and F≥3 or M≥3 or self-reported decline","Remaining customer group"))) -> R, F and M all ≥3, but not Champion | H15: =IF(F15="Champions / Highly Loyal","Advocacy, recognition and premium loyalty",IF(F15="Loyal Customers","Cross-sell, bundles and loyalty",IF(F15="Potential Loyalists","Build frequency and basket size",IF(F15="At-Risk Customers","Personalized win-back and service recovery","Low-cost reactivation / selective offers")))) -> Cross-sell, bundles and loyalty
A16: ='RFM Analysis'!A16 -> M012 | B16: ='RFM Analysis'!I16 -> 4 | C16: ='RFM Analysis'!D16 -> 2 | D16: ='RFM Analysis'!F16 -> 1 | E16: ='RFM Analysis'!H16 -> 1 | F16: =IF(AND(C16>=4,D16>=4,E16>=4),"Champions / Highly Loyal",IF(AND(C16>=3,D16>=3,E16>=3),"Loyal Customers",IF(AND(C16<=2,OR(D16>=3,E16>=3,'Customer Response Tracker'!J16="Yes")),"At-Risk Customers",IF(C16>=4,"Potential Loyalists","Inactive / Low Engagement")))) -> At-Risk Customers | G16: =IF(F16="Champions / Highly Loyal","R, F and M all ≥4",IF(F16="Loyal Customers","R, F and M all ≥3, but not Champion",IF(F16="At-Risk Customers","R≤2 and F≥3 or M≥3 or self-reported decline","Remaining customer group"))) -> R≤2 and F≥3 or M≥3 or self-reported decline | H16: =IF(F16="Champions / Highly Loyal","Advocacy, recognition and premium loyalty",IF(F16="Loyal Customers","Cross-sell, bundles and loyalty",IF(F16="Potential Loyalists","Build frequency and basket size",IF(F16="At-Risk Customers","Personalized win-back and service recovery","Low-cost reactivation / selective offers")))) -> Personalized win-back and service recovery
... A84: ='RFM Analysis'!A84 -> M080 | B84: ='RFM Analysis'!I84 -> 11 | C84: ='RFM Analysis'!D84 -> 3 | D84: ='RFM Analysis'!F84 -> 5 | E84: ='RFM Analysis'!H84 -> 3 | F84: =IF(AND(C84>=4,D84>=4,E84>=4),"Champions / Highly Loyal",IF(AND(C84>=3,D84>=3,E84>=3),"Loyal Customers",IF(AND(C84<=2,OR(D84>=3,E84>=3,'Customer Response Tracker'!J84="Yes")),"At-Risk Customers",IF(C84>=4,"Potential Loyalists","Inactive / Low Engagement")))) -> Loyal Customers | G84: =IF(F84="Champions / Highly Loyal","R, F and M all ≥4",IF(F84="Loyal Customers","R, F and M all ≥3, but not Champion",IF(F84="At-Risk Customers","R≤2 and F≥3 or M≥3 or self-reported decline","Remaining customer group"))) -> R, F and M all ≥3, but not Champion | H84: =IF(F84="Champions / Highly Loyal","Advocacy, recognition and premium loyalty",IF(F84="Loyal Customers","Cross-sell, bundles and loyalty",IF(F84="Potential Loyalists","Build frequency and basket size",IF(F84="At-Risk Customers","Personalized win-back and service recovery","Low-cost reactivation / selective offers")))) -> Cross-sell, bundles and loyalty
A87: Segment | B87: Customers | C87: Percentage
A88: Champions / Highly Loyal | B88: =COUNTIF($F$5:$F$84,A88) -> 9 | C88: =B88/COUNTA($A$5:$A$84) -> 0.1125
A89: Loyal Customers | B89: =COUNTIF($F$5:$F$84,A89) -> 20 | C89: =B89/COUNTA($A$5:$A$84) -> 0.25
A90: Potential Loyalists | B90: =COUNTIF($F$5:$F$84,A90) -> 14 | C90: =B90/COUNTA($A$5:$A$84) -> 0.175
A91: At-Risk Customers | B91: =COUNTIF($F$5:$F$84,A91) -> 16 | C91: =B91/COUNTA($A$5:$A$84) -> 0.2
A92: Inactive / Low Engagement | B92: =COUNTIF($F$5:$F$84,A92) -> 21 | C92: =B92/COUNTA($A$5:$A$84) -> 0.2625
A93: Total | B93: =SUM(B88:B92) -> 80 | C93: =SUM(C88:C92) -> 1

Sheet At-Risk Analysis
A1: Momo Hut — Strict Behavioural At-Risk Analysis
A2: At-Risk = YES only when ALL three conditions hold: Recency Days > 30, Earlier Visits/Month ≥ 4, Current Visits/Month < Earlier Visits/Month.
A4: Customer ID | B4: Earlier Visits/Month | C4: Current Visits/Month | D4: Most Recent Visit | E4: Recency Days | F4: RFM Score | G4: At-Risk Status | H4: At-Risk Reason | I4: Visit Drop
A5: ='Customer Response Tracker'!A5 -> M001 | B5: ='Customer Response Tracker'!E5 -> 8 | C5: ='Customer Response Tracker'!D5 -> 5 | D5: ='RFM Analysis'!B5 -> 46263 | E5: ='RFM Analysis'!C5 -> 2 | F5: ='RFM Analysis'!I5 -> 13 | G5: =IF(AND(E5>30,B5>=4,C5<B5),"Yes","No") -> No | H5: =IF(G5="Yes","Previously regular customer, now less frequent and inactive for >30 days","Does not meet all three strict criteria") -> Does not meet all three strict criteria | I5: =B5-C5 -> 3
A6: ='Customer Response Tracker'!A6 -> M002 | B6: ='Customer Response Tracker'!E6 -> 2 | C6: ='Customer Response Tracker'!D6 -> 1 | D6: ='RFM Analysis'!B6 -> 46261 | E6: ='RFM Analysis'!C6 -> 4 | F6: ='RFM Analysis'!I6 -> 7 | G6: =IF(AND(E6>30,B6>=4,C6<B6),"Yes","No") -> No | H6: =IF(G6="Yes","Previously regular customer, now less frequent and inactive for >30 days","Does not meet all three strict criteria") -> Does not meet all three strict criteria | I6: =B6-C6 -> 1
A7: ='Customer Response Tracker'!A7 -> M003 | B7: ='Customer Response Tracker'!E7 -> 6 | C7: ='Customer Response Tracker'!D7 -> 1 | D7: ='RFM Analysis'!B7 -> 46233 | E7: ='RFM Analysis'!C7 -> 32 | F7: ='RFM Analysis'!I7 -> 8 | G7: =IF(AND(E7>30,B7>=4,C7<B7),"Yes","No") -> Yes | H7: =IF(G7="Yes","Previously regular customer, now less frequent and inactive for >30 days","Does not meet all three strict criteria") -> Previously regular customer, now less frequent and inactive for >30 days | I7: =B7-C7 -> 5
A8: ='Customer Response Tracker'!A8 -> M004 | B8: ='Customer Response Tracker'!E8 -> 4 | C8: ='Customer Response Tracker'!D8 -> 6 | D8: ='RFM Analysis'!B8 -> 46253 | E8: ='RFM Analysis'!C8 -> 12 | F8: ='RFM Analysis'!I8 -> 9 | G8: =IF(AND(E8>30,B8>=4,C8<B8),"Yes","No") -> No | H8: =IF(G8="Yes","Previously regular customer, now less frequent and inactive for >30 days","Does not meet all three strict criteria") -> Does not meet all three strict criteria | I8: =B8-C8 -> -2
A9: ='Customer Response Tracker'!A9 -> M005 | B9: ='Customer Response Tracker'!E9 -> 3 | C9: ='Customer Response Tracker'!D9 -> 2 | D9: ='RFM Analysis'!B9 -> 46221 | E9: ='RFM Analysis'!C9 -> 44 | F9: ='RFM Analysis'!I9 -> 9 | G9: =IF(AND(E9>30,B9>=4,C9<B9),"Yes","No") -> No | H9: =IF(G9="Yes","Previously regular customer, now less frequent and inactive for >30 days","Does not meet all three strict criteria") -> Does not meet all three strict criteria | I9: =B9-C9 -> 1
A10: ='Customer Response Tracker'!A10 -> M006 | B10: ='Customer Response Tracker'!E10 -> 2 | C10: ='Customer Response Tracker'!D10 -> 3 | D10: ='RFM Analysis'!B10 -> 46256 | E10: ='RFM Analysis'!C10 -> 9 | F10: ='RFM Analysis'!I10 -> 12 | G10: =IF(AND(E10>30,B10>=4,C10<B10),"Yes","No") -> No | H10: =IF(G10="Yes","Previously regular customer, now less frequent and inactive for >30 days","Does not meet all three strict criteria") -> Does not meet all three strict criteria | I10: =B10-C10 -> -1
A11: ='Customer Response Tracker'!A11 -> M007 | B11: ='Customer Response Tracker'!E11 -> 6 | C11: ='Customer Response Tracker'!D11 -> 7 | D11: ='RFM Analysis'!B11 -> 46237 | E11: ='RFM Analysis'!C11 -> 28 | F11: ='RFM Analysis'!I11 -> 10 | G11: =IF(AND(E11>30,B11>=4,C11<B11),"Yes","No") -> No | H11: =IF(G11="Yes","Previously regular customer, now less frequent and inactive for >30 days","Does not meet all three strict criteria") -> Does not meet all three strict criteria | I11: =B11-C11 -> -1
A12: ='Customer Response Tracker'!A12 -> M008 | B12: ='Customer Response Tracker'!E12 -> 7 | C12: ='Customer Response Tracker'!D12 -> 1 | D12: ='RFM Analysis'!B12 -> 46232 | E12: ='RFM Analysis'!C12 -> 33 | F12: ='RFM Analysis'!I12 -> 4 | G12: =IF(AND(E12>30,B12>=4,C12<B12),"Yes","No") -> Yes | H12: =IF(G12="Yes","Previously regular customer, now less frequent and inactive for >30 days","Does not meet all three strict criteria") -> Previously regular customer, now less frequent and inactive for >30 days | I12: =B12-C12 -> 6
A13: ='Customer Response Tracker'!A13 -> M009 | B13: ='Customer Response Tracker'!E13 -> 2 | C13: ='Customer Response Tracker'!D13 -> 4 | D13: ='RFM Analysis'!B13 -> 46253 | E13: ='RFM Analysis'!C13 -> 12 | F13: ='RFM Analysis'!I13 -> 10 | G13: =IF(AND(E13>30,B13>=4,C13<B13),"Yes","No") -> No | H13: =IF(G13="Yes","Previously regular customer, now less frequent and inactive for >30 days","Does not meet all three strict criteria") -> Does not meet all three strict criteria | I13: =B13-C13 -> -2
A14: ='Customer Response Tracker'!A14 -> M010 | B14: ='Customer Response Tracker'!E14 -> 5 | C14: ='Customer Response Tracker'!D14 -> 6 | D14: ='RFM Analysis'!B14 -> 46249 | E14: ='RFM Analysis'!C14 -> 16 | F14: ='RFM Analysis'!I14 -> 8 | G14: =IF(AND(E14>30,B14>=4,C14<B14),"Yes","No") -> No | H14: =IF(G14="Yes","Previously regular customer, now less frequent and inactive for >30 days","Does not meet all three strict criteria") -> Does not meet all three strict criteria | I14: =B14-C14 -> -1
A15: ='Customer Response Tracker'!A15 -> M011 | B15: ='Customer Response Tracker'!E15 -> 5 | C15: ='Customer Response Tracker'!D15 -> 3 | D15: ='RFM Analysis'!B15 -> 46259 | E15: ='RFM Analysis'!C15 -> 6 | F15: ='RFM Analysis'!I15 -> 11 | G15: =IF(AND(E15>30,B15>=4,C15<B15),"Yes","No") -> No | H15: =IF(G15="Yes","Previously regular customer, now less frequent and inactive for >30 days","Does not meet all three strict criteria") -> Does not meet all three strict criteria | I15: =B15-C15 -> 2
A16: ='Customer Response Tracker'!A16 -> M012 | B16: ='Customer Response Tracker'!E16 -> 8 | C16: ='Customer Response Tracker'!D16 -> 1 | D16: ='RFM Analysis'!B16 -> 46230 | E16: ='RFM Analysis'!C16 -> 35 | F16: ='RFM Analysis'!I16 -> 4 | G16: =IF(AND(E16>30,B16>=4,C16<B16),"Yes","No") -> Yes | H16: =IF(G16="Yes","Previously regular customer, now less frequent and inactive for >30 days","Does not meet all three strict criteria") -> Previously regular customer, now less frequent and inactive for >30 days | I16: =B16-C16 -> 7
... A84: ='Customer Response Tracker'!A84 -> M080 | B84: ='Customer Response Tracker'!E84 -> 8 | C84: ='Customer Response Tracker'!D84 -> 10 | D84: ='RFM Analysis'!B84 -> 46239 | E84: ='RFM Analysis'!C84 -> 26 | F84: ='RFM Analysis'!I84 -> 11 | G84: =IF(AND(E84>30,B84>=4,C84<B84),"Yes","No") -> No | H84: =IF(G84="Yes","Previously regular customer, now less frequent and inactive for >30 days","Does not meet all three strict criteria") -> Does not meet all three strict criteria | I84: =B84-C84 -> -2
A87: Strict At-Risk Customers | B87: =COUNTIF(G5:G84,"Yes") -> 14
A88: Strict At-Risk Rate | B88: =B87/COUNTA(A5:A84) -> 0.175
A89: RFM-based At-Risk Customers | B89: =COUNTIF('Customer Segmentation'!F5:F84,"At-Risk Customers") -> 16
A90: Important | B90: RFM-based At-Risk and strict behavioural At-Risk are different lenses and must not be merged.

Sheet At-Risk Insights
A1: Momo Hut — At-Risk Insights (Reasons, Satisfaction & Offers)
A2: Scope: only customers flagged Yes by the strict behavioural At-Risk rule.
A4: Customer ID | B4: Earlier Visits | C4: Current Visits | D4: Recency Days | E4: Satisfaction | F4: Reason for Reduced Visits | G4: Preferred Offer | H4: Reason Category | I4: Loyalty Interest | J4: Average Spend
A5: ='At-Risk Analysis'!A7 -> M003 | B5: ='At-Risk Analysis'!B7 -> 6 | C5: ='At-Risk Analysis'!C7 -> 1 | D5: ='At-Risk Analysis'!E7 -> 32 | E5: ='Customer Response Tracker'!I7 -> 2 | F5: ='Customer Response Tracker'!K7 -> Food taste has become inconsistent on recent visits | G5: ='Customer Response Tracker'!M7 -> Combo meal deal | H5: =IF(OR(ISNUMBER(SEARCH("taste",F5)),ISNUMBER(SEARCH("portion",F5)),ISNUMBER(SEARCH("momos",F5)),ISNUMBER(SEARCH("packaging",F5)),ISNUMBER(SEARCH("variety",F5)),ISNUMBER(SEARCH("menu",F5))),"Product / Quality",IF(OR(ISNUMBER(SEARCH("service",F5)),ISNUMBER(SEARCH("waiting",F5)),ISNUMBER(SEARCH("rush",F5)),ISNUMBER(SEARCH("seating",F5)),ISNUMBER(SEARCH("crowded",F5))),"Service / Experience",IF(OR(ISNUMBER(SEARCH("working from home",F5)),ISNUMBER(SEARCH("commute",F5)),ISNUMBER(SEARCH("convenient",F5))),"Convenience / Location",IF(OR(ISNUMBER(SEARCH("schedule",F5)),ISNUMBER(SEARCH("busy",F5))),"Time / Schedule",IF(OR(ISNUMBER(SEARCH("affordable",F5)),ISNUMBER(SEARCH("budget",F5)),ISNUMBER(SEARCH("price",F5))),"Price / Affordability","Other"))))) -> Product / Quality | I5: ='Customer Response Tracker'!L7 -> Maybe | J5: ='Customer Response Tracker'!H7 -> 402
A6: ='At-Risk Analysis'!A12 -> M008 | B6: ='At-Risk Analysis'!B12 -> 7 | C6: ='At-Risk Analysis'!C12 -> 1 | D6: ='At-Risk Analysis'!E12 -> 33 | E6: ='Customer Response Tracker'!I12 -> 3 | F6: ='Customer Response Tracker'!K12 -> Service is slow during the evening rush | G6: ='Customer Response Tracker'!M12 -> 10% weekday discount | H6: =IF(OR(ISNUMBER(SEARCH("taste",F6)),ISNUMBER(SEARCH("portion",F6)),ISNUMBER(SEARCH("momos",F6)),ISNUMBER(SEARCH("packaging",F6)),ISNUMBER(SEARCH("variety",F6)),ISNUMBER(SEARCH("menu",F6))),"Product / Quality",IF(OR(ISNUMBER(SEARCH("service",F6)),ISNUMBER(SEARCH("waiting",F6)),ISNUMBER(SEARCH("rush",F6)),ISNUMBER(SEARCH("seating",F6)),ISNUMBER(SEARCH("crowded",F6))),"Service / Experience",IF(OR(ISNUMBER(SEARCH("working from home",F6)),ISNUMBER(SEARCH("commute",F6)),ISNUMBER(SEARCH("convenient",F6))),"Convenience / Location",IF(OR(ISNUMBER(SEARCH("schedule",F6)),ISNUMBER(SEARCH("busy",F6))),"Time / Schedule",IF(OR(ISNUMBER(SEARCH("affordable",F6)),ISNUMBER(SEARCH("budget",F6)),ISNUMBER(SEARCH("price",F6))),"Price / Affordability","Other"))))) -> Service / Experience | I6: ='Customer Response Tracker'!L12 -> Yes | J6: ='Customer Response Tracker'!H12 -> 221
A7: ='At-Risk Analysis'!A16 -> M012 | B7: ='At-Risk Analysis'!B16 -> 8 | C7: ='At-Risk Analysis'!C16 -> 1 | D7: ='At-Risk Analysis'!E16 -> 35 | E7: ='Customer Response Tracker'!I16 -> 2 | F7: ='Customer Response Tracker'!K16 -> Portion size feels smaller than before | G7: ='Customer Response Tracker'!M16 -> Free beverage add-on | H7: =IF(OR(ISNUMBER(SEARCH("taste",F7)),ISNUMBER(SEARCH("portion",F7)),ISNUMBER(SEARCH("momos",F7)),ISNUMBER(SEARCH("packaging",F7)),ISNUMBER(SEARCH("variety",F7)),ISNUMBER(SEARCH("menu",F7))),"Product / Quality",IF(OR(ISNUMBER(SEARCH("service",F7)),ISNUMBER(SEARCH("waiting",F7)),ISNUMBER(SEARCH("rush",F7)),ISNUMBER(SEARCH("seating",F7)),ISNUMBER(SEARCH("crowded",F7))),"Service / Experience",IF(OR(ISNUMBER(SEARCH("working from home",F7)),ISNUMBER(SEARCH("commute",F7)),ISNUMBER(SEARCH("convenient",F7))),"Convenience / Location",IF(OR(ISNUMBER(SEARCH("schedule",F7)),ISNUMBER(SEARCH("busy",F7))),"Time / Schedule",IF(OR(ISNUMBER(SEARCH("affordable",F7)),ISNUMBER(SEARCH("budget",F7)),ISNUMBER(SEARCH("price",F7))),"Price / Affordability","Other"))))) -> Product / Quality | I7: ='Customer Response Tracker'!L16 -> Maybe | J7: ='Customer Response Tracker'!H16 -> 196
A8: ='At-Risk Analysis'!A20 -> M016 | B8: ='At-Risk Analysis'!B20 -> 6 | C8: ='At-Risk Analysis'!C20 -> 1 | D8: ='At-Risk Analysis'!E20 -> 38 | E8: ='Customer Response Tracker'!I20 -> 1 | F8: ='Customer Response Tracker'!K20 -> Started working from home, so the outlet is less convenient | G8: ='Customer Response Tracker'!M20 -> Loyalty stamp card | H8: =IF(OR(ISNUMBER(SEARCH("taste",F8)),ISNUMBER(SEARCH("portion",F8)),ISNUMBER(SEARCH("momos",F8)),ISNUMBER(SEARCH("packaging",F8)),ISNUMBER(SEARCH("variety",F8)),ISNUMBER(SEARCH("menu",F8))),"Product / Quality",IF(OR(ISNUMBER(SEARCH("service",F8)),ISNUMBER(SEARCH("waiting",F8)),ISNUMBER(SEARCH("rush",F8)),ISNUMBER(SEARCH("seating",F8)),ISNUMBER(SEARCH("crowded",F8))),"Service / Experience",IF(OR(ISNUMBER(SEARCH("working from home",F8)),ISNUMBER(SEARCH("commute",F8)),ISNUMBER(SEARCH("convenient",F8))),"Convenience / Location",IF(OR(ISNUMBER(SEARCH("schedule",F8)),ISNUMBER(SEARCH("busy",F8))),"Time / Schedule",IF(OR(ISNUMBER(SEARCH("affordable",F8)),ISNUMBER(SEARCH("budget",F8)),ISNUMBER(SEARCH("price",F8))),"Price / Affordability","Other"))))) -> Convenience / Location | I8: ='Customer Response Tracker'!L20 -> Yes | J8: ='Customer Response Tracker'!H20 -> 386
A9: ='At-Risk Analysis'!A24 -> M020 | B9: ='At-Risk Analysis'!B24 -> 8 | C9: ='At-Risk Analysis'!C24 -> 2 | D9: ='At-Risk Analysis'!E24 -> 50 | E9: ='Customer Response Tracker'!I24 -> 4 | F9: ='Customer Response Tracker'!K24 -> Too much waiting time for takeaway orders | G9: ='Customer Response Tracker'!M24 -> 10% weekday discount | H9: =IF(OR(ISNUMBER(SEARCH("taste",F9)),ISNUMBER(SEARCH("portion",F9)),ISNUMBER(SEARCH("momos",F9)),ISNUMBER(SEARCH("packaging",F9)),ISNUMBER(SEARCH("variety",F9)),ISNUMBER(SEARCH("menu",F9))),"Product / Quality",IF(OR(ISNUMBER(SEARCH("service",F9)),ISNUMBER(SEARCH("waiting",F9)),ISNUMBER(SEARCH("rush",F9)),ISNUMBER(SEARCH("seating",F9)),ISNUMBER(SEARCH("crowded",F9))),"Service / Experience",IF(OR(ISNUMBER(SEARCH("working from home",F9)),ISNUMBER(SEARCH("commute",F9)),ISNUMBER(SEARCH("convenient",F9))),"Convenience / Location",IF(OR(ISNUMBER(SEARCH("schedule",F9)),ISNUMBER(SEARCH("busy",F9))),"Time / Schedule",IF(OR(ISNUMBER(SEARCH("affordable",F9)),ISNUMBER(SEARCH("budget",F9)),ISNUMBER(SEARCH("price",F9))),"Price / Affordability","Other"))))) -> Service / Experience | I9: ='Customer Response Tracker'!L24 -> Maybe | J9: ='Customer Response Tracker'!H24 -> 341
A10: ='At-Risk Analysis'!A29 -> M025 | B10: ='At-Risk Analysis'!B29 -> 5 | C10: ='At-Risk Analysis'!C29 -> 3 | D10: ='At-Risk Analysis'!E29 -> 43 | E10: ='Customer Response Tracker'!I29 -> 3 | F10: ='Customer Response Tracker'!K29 -> Would like more affordable combo options | G10: ='Customer Response Tracker'!M29 -> Combo meal deal | H10: =IF(OR(ISNUMBER(SEARCH("taste",F10)),ISNUMBER(SEARCH("portion",F10)),ISNUMBER(SEARCH("momos",F10)),ISNUMBER(SEARCH("packaging",F10)),ISNUMBER(SEARCH("variety",F10)),ISNUMBER(SEARCH("menu",F10))),"Product / Quality",IF(OR(ISNUMBER(SEARCH("service",F10)),ISNUMBER(SEARCH("waiting",F10)),ISNUMBER(SEARCH("rush",F10)),ISNUMBER(SEARCH("seating",F10)),ISNUMBER(SEARCH("crowded",F10))),"Service / Experience",IF(OR(ISNUMBER(SEARCH("working from home",F10)),ISNUMBER(SEARCH("commute",F10)),ISNUMBER(SEARCH("convenient",F10))),"Convenience / Location",IF(OR(ISNUMBER(SEARCH("schedule",F10)),ISNUMBER(SEARCH("busy",F10))),"Time / Schedule",IF(OR(ISNUMBER(SEARCH("affordable",F10)),ISNUMBER(SEARCH("budget",F10)),ISNUMBER(SEARCH("price",F10))),"Price / Affordability","Other"))))) -> Price / Affordability | I10: ='Customer Response Tracker'!L29 -> Maybe | J10: ='Customer Response Tracker'!H29 -> 397
A11: ='At-Risk Analysis'!A35 -> M031 | B11: ='At-Risk Analysis'!B35 -> 6 | C11: ='At-Risk Analysis'!C35 -> 3 | D11: ='At-Risk Analysis'!E35 -> 44 | E11: ='Customer Response Tracker'!I35 -> 2 | F11: ='Customer Response Tracker'!K35 -> Dining area feels crowded at peak hours | G11: ='Customer Response Tracker'!M35 -> Loyalty stamp card | H11: =IF(OR(ISNUMBER(SEARCH("taste",F11)),ISNUMBER(SEARCH("portion",F11)),ISNUMBER(SEARCH("momos",F11)),ISNUMBER(SEARCH("packaging",F11)),ISNUMBER(SEARCH("variety",F11)),ISNUMBER(SEARCH("menu",F11))),"Product / Quality",IF(OR(ISNUMBER(SEARCH("service",F11)),ISNUMBER(SEARCH("waiting",F11)),ISNUMBER(SEARCH("rush",F11)),ISNUMBER(SEARCH("seating",F11)),ISNUMBER(SEARCH("crowded",F11))),"Service / Experience",IF(OR(ISNUMBER(SEARCH("working from home",F11)),ISNUMBER(SEARCH("commute",F11)),ISNUMBER(SEARCH("convenient",F11))),"Convenience / Location",IF(OR(ISNUMBER(SEARCH("schedule",F11)),ISNUMBER(SEARCH("busy",F11))),"Time / Schedule",IF(OR(ISNUMBER(SEARCH("affordable",F11)),ISNUMBER(SEARCH("budget",F11)),ISNUMBER(SEARCH("price",F11))),"Price / Affordability","Other"))))) -> Service / Experience | I11: ='Customer Response Tracker'!L35 -> Yes | J11: ='Customer Response Tracker'!H35 -> 256
A12: ='At-Risk Analysis'!A41 -> M037 | B12: ='At-Risk Analysis'!B41 -> 8 | C12: ='At-Risk Analysis'!C41 -> 3 | D12: ='At-Risk Analysis'!E41 -> 32 | E12: ='Customer Response Tracker'!I41 -> 4 | F12: ='Customer Response Tracker'!K41 -> Menu has not changed much in recent months | G12: ='Customer Response Tracker'!M41 -> Free beverage add-on | H12: =IF(OR(ISNUMBER(SEARCH("taste",F12)),ISNUMBER(SEARCH("portion",F12)),ISNUMBER(SEARCH("momos",F12)),ISNUMBER(SEARCH("packaging",F12)),ISNUMBER(SEARCH("variety",F12)),ISNUMBER(SEARCH("menu",F12))),"Product / Quality",IF(OR(ISNUMBER(SEARCH("service",F12)),ISNUMBER(SEARCH("waiting",F12)),ISNUMBER(SEARCH("rush",F12)),ISNUMBER(SEARCH("seating",F12)),ISNUMBER(SEARCH("crowded",F12))),"Service / Experience",IF(OR(ISNUMBER(SEARCH("working from home",F12)),ISNUMBER(SEARCH("commute",F12)),ISNUMBER(SEARCH("convenient",F12))),"Convenience / Location",IF(OR(ISNUMBER(SEARCH("schedule",F12)),ISNUMBER(SEARCH("busy",F12))),"Time / Schedule",IF(OR(ISNUMBER(SEARCH("affordable",F12)),ISNUMBER(SEARCH("budget",F12)),ISNUMBER(SEARCH("price",F12))),"Price / Affordability","Other"))))) -> Product / Quality | I12: ='Customer Response Tracker'!L41 -> Maybe | J12: ='Customer Response Tracker'!H41 -> 323
A13: ='At-Risk Analysis'!A48 -> M044 | B13: ='At-Risk Analysis'!B48 -> 4 | C13: ='At-Risk Analysis'!C48 -> 1 | D13: ='At-Risk Analysis'!E48 -> 51 | E13: ='Customer Response Tracker'!I48 -> 2 | F13: ='Customer Response Tracker'!K48 -> More seating would make visits easier | G13: ='Customer Response Tracker'!M48 -> Referral reward | H13: =IF(OR(ISNUMBER(SEARCH("taste",F13)),ISNUMBER(SEARCH("portion",F13)),ISNUMBER(SEARCH("momos",F13)),ISNUMBER(SEARCH("packaging",F13)),ISNUMBER(SEARCH("variety",F13)),ISNUMBER(SEARCH("menu",F13))),"Product / Quality",IF(OR(ISNUMBER(SEARCH("service",F13)),ISNUMBER(SEARCH("waiting",F13)),ISNUMBER(SEARCH("rush",F13)),ISNUMBER(SEARCH("seating",F13)),ISNUMBER(SEARCH("crowded",F13))),"Service / Experience",IF(OR(ISNUMBER(SEARCH("working from home",F13)),ISNUMBER(SEARCH("commute",F13)),ISNUMBER(SEARCH("convenient",F13))),"Convenience / Location",IF(OR(ISNUMBER(SEARCH("schedule",F13)),ISNUMBER(SEARCH("busy",F13))),"Time / Schedule",IF(OR(ISNUMBER(SEARCH("affordable",F13)),ISNUMBER(SEARCH("budget",F13)),ISNUMBER(SEARCH("price",F13))),"Price / Affordability","Other"))))) -> Service / Experience | I13: ='Customer Response Tracker'!L48 -> Yes | J13: ='Customer Response Tracker'!H48 -> 291
A14: ='At-Risk Analysis'!A54 -> M050 | B14: ='At-Risk Analysis'!B54 -> 4 | C14: ='At-Risk Analysis'!C54 -> 1 | D14: ='At-Risk Analysis'!E54 -> 38 | E14: ='Customer Response Tracker'!I54 -> 2 | F14: ='Customer Response Tracker'!K54 -> Sometimes the momos are not served hot enough | G14: ='Customer Response Tracker'!M54 -> Loyalty stamp card | H14: =IF(OR(ISNUMBER(SEARCH("taste",F14)),ISNUMBER(SEARCH("portion",F14)),ISNUMBER(SEARCH("momos",F14)),ISNUMBER(SEARCH("packaging",F14)),ISNUMBER(SEARCH("variety",F14)),ISNUMBER(SEARCH("menu",F14))),"Product / Quality",IF(OR(ISNUMBER(SEARCH("service",F14)),ISNUMBER(SEARCH("waiting",F14)),ISNUMBER(SEARCH("rush",F14)),ISNUMBER(SEARCH("seating",F14)),ISNUMBER(SEARCH("crowded",F14))),"Service / Experience",IF(OR(ISNUMBER(SEARCH("working from home",F14)),ISNUMBER(SEARCH("commute",F14)),ISNUMBER(SEARCH("convenient",F14))),"Convenience / Location",IF(OR(ISNUMBER(SEARCH("schedule",F14)),ISNUMBER(SEARCH("busy",F14))),"Time / Schedule",IF(OR(ISNUMBER(SEARCH("affordable",F14)),ISNUMBER(SEARCH("budget",F14)),ISNUMBER(SEARCH("price",F14))),"Price / Affordability","Other"))))) -> Product / Quality | I14: ='Customer Response Tracker'!L54 -> Yes | J14: ='Customer Response Tracker'!H54 -> 372
A15: ='At-Risk Analysis'!A60 -> M056 | B15: ='At-Risk Analysis'!B60 -> 8 | C15: ='At-Risk Analysis'!C60 -> 1 | D15: ='At-Risk Analysis'!E60 -> 36 | E15: ='Customer Response Tracker'!I60 -> 1 | F15: ='Customer Response Tracker'!K60 -> Busy college schedule leaves less time to visit | G15: ='Customer Response Tracker'!M60 -> 10% weekday discount | H15: =IF(OR(ISNUMBER(SEARCH("taste",F15)),ISNUMBER(SEARCH("portion",F15)),ISNUMBER(SEARCH("momos",F15)),ISNUMBER(SEARCH("packaging",F15)),ISNUMBER(SEARCH("variety",F15)),ISNUMBER(SEARCH("menu",F15))),"Product / Quality",IF(OR(ISNUMBER(SEARCH("service",F15)),ISNUMBER(SEARCH("waiting",F15)),ISNUMBER(SEARCH("rush",F15)),ISNUMBER(SEARCH("seating",F15)),ISNUMBER(SEARCH("crowded",F15))),"Service / Experience",IF(OR(ISNUMBER(SEARCH("working from home",F15)),ISNUMBER(SEARCH("commute",F15)),ISNUMBER(SEARCH("convenient",F15))),"Convenience / Location",IF(OR(ISNUMBER(SEARCH("schedule",F15)),ISNUMBER(SEARCH("busy",F15))),"Time / Schedule",IF(OR(ISNUMBER(SEARCH("affordable",F15)),ISNUMBER(SEARCH("budget",F15)),ISNUMBER(SEARCH("price",F15))),"Price / Affordability","Other"))))) -> Time / Schedule | I15: ='Customer Response Tracker'!L60 -> Yes | J15: ='Customer Response Tracker'!H60 -> 240
A16: ='At-Risk Analysis'!A67 -> M063 | B16: ='At-Risk Analysis'!B67 -> 9 | C16: ='At-Risk Analysis'!C67 -> 3 | D16: ='At-Risk Analysis'!E67 -> 46 | E16: ='Customer Response Tracker'!I67 -> 2 | F16: ='Customer Response Tracker'!K67 -> Packaging leaks during takeaway | G16: ='Customer Response Tracker'!M67 -> Free beverage add-on | H16: =IF(OR(ISNUMBER(SEARCH("taste",F16)),ISNUMBER(SEARCH("portion",F16)),ISNUMBER(SEARCH("momos",F16)),ISNUMBER(SEARCH("packaging",F16)),ISNUMBER(SEARCH("variety",F16)),ISNUMBER(SEARCH("menu",F16))),"Product / Quality",IF(OR(ISNUMBER(SEARCH("service",F16)),ISNUMBER(SEARCH("waiting",F16)),ISNUMBER(SEARCH("rush",F16)),ISNUMBER(SEARCH("seating",F16)),ISNUMBER(SEARCH("crowded",F16))),"Service / Experience",IF(OR(ISNUMBER(SEARCH("working from home",F16)),ISNUMBER(SEARCH("commute",F16)),ISNUMBER(SEARCH("convenient",F16))),"Convenience / Location",IF(OR(ISNUMBER(SEARCH("schedule",F16)),ISNUMBER(SEARCH("busy",F16))),"Time / Schedule",IF(OR(ISNUMBER(SEARCH("affordable",F16)),ISNUMBER(SEARCH("budget",F16)),ISNUMBER(SEARCH("price",F16))),"Price / Affordability","Other"))))) -> Product / Quality | I16: ='Customer Response Tracker'!L67 -> Yes | J16: ='Customer Response Tracker'!H67 -> 392
A17: ='At-Risk Analysis'!A74 -> M070 | B17: ='At-Risk Analysis'!B74 -> 6 | C17: ='At-Risk Analysis'!C74 -> 2 | D17: ='At-Risk Analysis'!E74 -> 53 | E17: ='Customer Response Tracker'!I74 -> 3 | F17: ='Customer Response Tracker'!K74 -> Would prefer more variety in Chinese starters | G17: ='Customer Response Tracker'!M74 -> Combo meal deal | H17: =IF(OR(ISNUMBER(SEARCH("taste",F17)),ISNUMBER(SEARCH("portion",F17)),ISNUMBER(SEARCH("momos",F17)),ISNUMBER(SEARCH("packaging",F17)),ISNUMBER(SEARCH("variety",F17)),ISNUMBER(SEARCH("menu",F17))),"Product / Quality",IF(OR(ISNUMBER(SEARCH("service",F17)),ISNUMBER(SEARCH("waiting",F17)),ISNUMBER(SEARCH("rush",F17)),ISNUMBER(SEARCH("seating",F17)),ISNUMBER(SEARCH("crowded",F17))),"Service / Experience",IF(OR(ISNUMBER(SEARCH("working from home",F17)),ISNUMBER(SEARCH("commute",F17)),ISNUMBER(SEARCH("convenient",F17))),"Convenience / Location",IF(OR(ISNUMBER(SEARCH("schedule",F17)),ISNUMBER(SEARCH("busy",F17))),"Time / Schedule",IF(OR(ISNUMBER(SEARCH("affordable",F17)),ISNUMBER(SEARCH("budget",F17)),ISNUMBER(SEARCH("price",F17))),"Price / Affordability","Other"))))) -> Product / Quality | I17: ='Customer Response Tracker'!L74 -> Yes | J17: ='Customer Response Tracker'!H74 -> 297
A18: ='At-Risk Analysis'!A81 -> M077 | B18: ='At-Risk Analysis'!B81 -> 5 | C18: ='At-Risk Analysis'!C81 -> 2 | D18: ='At-Risk Analysis'!E81 -> 51 | E18: ='Customer Response Tracker'!I81 -> 4 | F18: ='Customer Response Tracker'!K81 -> Outlet is farther from my current commute | G18: ='Customer Response Tracker'!M81 -> Loyalty stamp card | H18: =IF(OR(ISNUMBER(SEARCH("taste",F18)),ISNUMBER(SEARCH("portion",F18)),ISNUMBER(SEARCH("momos",F18)),ISNUMBER(SEARCH("packaging",F18)),ISNUMBER(SEARCH("variety",F18)),ISNUMBER(SEARCH("menu",F18))),"Product / Quality",IF(OR(ISNUMBER(SEARCH("service",F18)),ISNUMBER(SEARCH("waiting",F18)),ISNUMBER(SEARCH("rush",F18)),ISNUMBER(SEARCH("seating",F18)),ISNUMBER(SEARCH("crowded",F18))),"Service / Experience",IF(OR(ISNUMBER(SEARCH("working from home",F18)),ISNUMBER(SEARCH("commute",F18)),ISNUMBER(SEARCH("convenient",F18))),"Convenience / Location",IF(OR(ISNUMBER(SEARCH("schedule",F18)),ISNUMBER(SEARCH("busy",F18))),"Time / Schedule",IF(OR(ISNUMBER(SEARCH("affordable",F18)),ISNUMBER(SEARCH("budget",F18)),ISNUMBER(SEARCH("price",F18))),"Price / Affordability","Other"))))) -> Convenience / Location | I18: ='Customer Response Tracker'!L81 -> Yes | J18: ='Customer Response Tracker'!H81 -> 260
A21: 1. Key Metrics | D21: 2. Reasons for Reduced Visits | H21: 3. Preferred Offers
A22: Strict At-Risk customers | B22: =COUNTA(A5:A18) -> 14 | D22: Product / Quality | E22: =COUNTIF($H$5:$H$18,D22) -> 6 | F22: =E22/$B$22 -> 0.42857143 | H22: Loyalty stamp card | I22: =COUNTIF($G$5:$G$18,H22) -> 4 | J22: =I22/$B$22 -> 0.28571429
A23: Average earlier visits/month | B23: =AVERAGE(B5:B18) -> 6.4285714 | D23: Service / Experience | E23: =COUNTIF($H$5:$H$18,D23) -> 4 | F23: =E23/$B$22 -> 0.28571429 | H23: Combo meal deal | I23: =COUNTIF($G$5:$G$18,H23) -> 3 | J23: =I23/$B$22 -> 0.21428571
A24: Average current visits/month | B24: =AVERAGE(C5:C18) -> 1.7857143 | D24: Convenience / Location | E24: =COUNTIF($H$5:$H$18,D24) -> 2 | F24: =E24/$B$22 -> 0.14285714 | H24: 10% weekday discount | I24: =COUNTIF($G$5:$G$18,H24) -> 3 | J24: =I24/$B$22 -> 0.21428571
A25: Average visit-frequency drop | B25: =AVERAGE(B5:B18)-AVERAGE(C5:C18) -> 4.6428571 | D25: Price / Affordability | E25: =COUNTIF($H$5:$H$18,D25) -> 1 | F25: =E25/$B$22 -> 0.071428571 | H25: Free beverage add-on | I25: =COUNTIF($G$5:$G$18,H25) -> 3 | J25: =I25/$B$22 -> 0.21428571
A26: Average recency days | B26: =AVERAGE(D5:D18) -> 41.571429 | D26: Time / Schedule | E26: =COUNTIF($H$5:$H$18,D26) -> 1 | F26: =E26/$B$22 -> 0.071428571 | H26: Referral reward | I26: =COUNTIF($G$5:$G$18,H26) -> 1 | J26: =I26/$B$22 -> 0.071428571
A27: Average satisfaction | B27: =AVERAGE(E5:E18) -> 2.5 | D27: Total | E27: =SUM(E22:E26) -> 14 | F27: =SUM(F22:F26) -> 1 | H27: Total | I27: =SUM(I22:I26) -> 14 | J27: =SUM(J22:J26) -> 1
A28: Customers with satisfaction 1–2 | B28: =COUNTIF(E5:E18,"<=2") -> 8
A29: Share with satisfaction 1–2 | B29: =B28/B22 -> 0.57142857
A30: Average spend/visit | B30: =AVERAGE(J5:J18) -> 312.42857

Sheet Retention Playbook
A1: Momo Hut — Retention Playbook
A2: Three measures selected from the simulated At-Risk findings; proposed, not implemented.
A4: Retention Measure | B4: Problem Addressed | C4: Target Customers | D4: How It Will Work | E4: Expected Benefit | F4: Primary KPI | G4: Owner | H4: Priority
A5: Personalized Comeback Offer | B5: Varied reasons for decline and low satisfaction | C5: All 14 strict At-Risk customers | D5: Send a personalized WhatsApp/SMS message using each customer's stated reason and preferred offer; include a 30-day redemption window. | E5: Shows that feedback was heard and gives a relevant reason to return. | F5: Offer redemption rate; repeat visit within 30 days | G5: Outlet Manager + Front-of-house | H5: 1
A6: Loyalty Stamp Card | B6: Strongest single preference is a loyalty-based reward | C6: 14 At-Risk customers first; then open to all customers | D6: Stamp 1 visit per qualifying purchase; reward after 8 visits. Start with the 4 At-Risk customers who selected the loyalty offer. | E6: Creates a repeat-visit habit and a visible reward path. | F6: Enrollments; redemption rate; repeat visits/month | G6: Outlet Manager + Cashier | H6: 2
